2021-03-24 08:25:39.414501    NameError:
 Traceback (most recent call last):
  File "C:\documents\OOP\app.py", line 37, in <module>
    Candidate.work(john)
  File "C:\documents\OOP\models.py", line 113, in work
    raise UnableToWorkExceptionPrint("I'm not hired yet")
NameError: name 'UnableToWorkExceptionPrint' is not defined

 
2021-03-24 08:25:39.416499    ValueError:
 Traceback (most recent call last):
  File "C:\documents\OOP\app.py", line 45, in <module>
    Employee.validate_email(oleg, "privet@oleg.com")
  File "C:\documents\OOP\models.py", line 38, in validate_email
    raise ValueError('email is in use')
ValueError: email is in use

 
